Workbook

Sheet Read Me
B2: Landscaping Business — 1-Year Financial Model (Jul 2026 – Jun 2027)
B3: Stage 1 deliverable: the quantitative engine underpinning the strategic plan.
B5: HOW TO USE THIS MODEL
B6: • Change only the BLUE cells. Black cells are formulas that recompute automatically.
B7: • Key assumptions are highlighted YELLOW on the Assumptions tab — start there.
B8: • The Model tab builds revenue, profit and cash month-by-month from those assumptions.
B9: • The Quarterly Summary tab rolls the months into the four plan quarters.
B11: COLOR LEGEND
B12: Blue text = an input you can change. Black text = a calculated formula. Green text = a link from another tab.
B14: IMPORTANT — THESE ARE PLANNING ASSUMPTIONS, NOT ACTUALS
B15: Every figure here is a reasoned estimate from our nine-domain analysis, to be replaced with real Homeworks data as it accumulates. The model is built to be re-run, not to be right on the first pass. The peak anchor ($4,500), retention, and project/mowing split are the assumptions most worth revisiting first.
B17: KEY OUTPUTS AT A GLANCE (recompute if you change inputs)
... B21: • $20K/month remains a 2028+ horizon goal, not a target within this plan window.

Sheet Assumptions
A1: ASSUMPTIONS (edit blue cells; yellow = highest-priority)
A3: REVENUE ANCHOR
A4: Peak-month revenue anchor (May/Jun) | B4: 4500 | C4: Validated: actual May 2026 = $4,908
A6: SERVICE MIX & CONTRIBUTION MARGINS
A7: Baseline project share of revenue | B7: 0.58 | C7: Data-derived from Jan-Jun 2026 actuals (was 80%)
A8: Baseline mowing share of revenue | B8: 0.42 | C8: Mostly commercial maintenance; residential recurring ~5%
A9: Project contribution margin | B9: 0.35 | C9: Before fixed overhead; Domain 2
A10: Existing mowing CM (@ $50/visit) | B10: 0.42 | C10: Before fixed overhead; Domain 2
A11: New mowing CM (@ $60/visit) | B11: 0.52 | C11: Higher price on same cost base
A12: Weekday-growth blended CM | B12: 0.38 | C12: Mixed project+mowing weekday work
A13: Baseline blended CM (derived) | B13: =B7*B9+B8*B10 -> 0.3794 | C13: Auto from shares + margins above
A15: PRICING
A16: Existing mowing $/visit | B16: 50 | C16: Grandfathered current clients
A17: New mowing $/visit (Spring 2027) | B17: 60 | C17: $60/hr basis on estimated time
A19: FIXED MONTHLY COSTS
A20: General liability insurance | B20: 36.56 | C20: $438.75/yr incl. doubled first month
A21: Workers' compensation | B21: 45.33 | C21: $544/yr
A22: Commercial auto | B22: 166.67 | C22: $2,000 / 6 months
A23: Payroll provider (base + 11 staff) | B23: 115 | C23: $49 + 11 x $6
A24: CRM — Homeworks Growth | B24: 299 | C24: Upgraded plan
A25: Equipment maintenance allocation | B25: 32.5 | C25: ~$390/yr mid-tier residential
A26: TOTAL FIXED MONTHLY | B26: =SUM(B20:B25) -> 695.06
A28: LABOR RATES (/hr)
A29: Crew member | B29: 20
A30: Crew lead | B30: 25
A32: CASH & CAPITAL
A33: Starting cash (1 Jul 2026) | B33: 1500 | C33: Planning anchor; mid-Jun '26 actual ~$800 post-payroll - confirm at first July check-in
A34: Operating reserve target | B34: 4000 | C34: Hard floor; raw bank balance; patient debt not netted; precondition for scaling
A35: Truck-risk cushion | B35: 2000 | C35: Truck hedge (rounded to $2k); priority claim once $4k floor secured
A36: Transmission diagnostic (Jul) | B36: 0 | C36: Done Jun 2026 (assessed; not worth repairing) - already incurred; no future outflow
A37: Electric blower + tarps (Sep) | B37: 400 | C37: Phase 1; regulation-compliant
A38: Xavier equity payout (Mar) | B38: 1500 | C38: External/family obligation
A39: Truck debt (deferrable, to self) | B39: 3800 | C39: No interest; excluded from base cash line
A40: Cash buffer target (reserve + truck hedge) | B40: =B34+B35 -> 6000 | C40: $6,000; raw bank balance; patient debt treated as equity
A42: DATA VALIDATION - Jan-Jun 2026 actuals (Homeworks)
A43: Total recorded revenue (Jan-Jun 2026) | B43: 9562.71 | C43: Reconciles across customer, service & P&L reports
A44: Peak month (May 2026) | B44: 4908 | C44: Confirms the $4,500 normalized anchor
A45: Recorded project share | B45: 0.58 | C45: Was assumed 80%
A46: Recorded maintenance share | B46: 0.42 | C46: Mostly the 2 commercial accounts
A47: Residential recurring mowing share | B47: 0.05 | C47: Growth engine starts near zero
...

Sheet Model
A1: MONTHLY MODEL (Jul 2026 – Jun 2027)
A3: ($ per month) | B3: Jul-26 | C3: Aug-26 | D3: Sep-26 | E3: Oct-26 | F3: Nov-26 | G3: Dec-26 | H3: Jan-27 | I3: Feb-27 | J3: Mar-27 | K3: Apr-27 | L3: May-27 | M3: Jun-27
A4: INPUTS
A5: Seasonal index (blended, 100 = peak) | B5: 92 | C5: 91 | D5: 99 | E5: 94 | F5: 73 | G5: 48 | H5: 23 | I5: 28 | J5: 59 | K5: 85 | L5: 100 | M5: 100
A6: Weekday-growth revenue ($) | B6: 0 | C6: 500 | D6: 1000 | E6: 1200 | F6: 800 | G6: 400 | H6: 200 | I6: 400 | J6: 800 | K6: 1200 | L6: 1500 | M6: 1800
A7: New mowing clients added | B7: 0 | C7: 0 | D7: 0 | E7: 0 | F7: 0 | G7: 0 | H7: 0 | I7: 2 | J7: 4 | K7: 4 | L7: 2 | M7: 0
A8: Cumulative new mowing clients | B8: =B7 -> 0 | C8: =B8+C7 -> 0 | D8: =C8+D7 -> 0 | E8: =D8+E7 -> 0 | F8: =E8+F7 -> 0 | G8: =F8+G7 -> 0 | H8: =G8+H7 -> 0 | I8: =H8+I7 -> 2 | J8: =I8+J7 -> 6 | ... M8: =L8+M7 -> 12
A9: Visits per client this month | B9: 4 | C9: 4 | D9: 4 | E9: 3 | F9: 2 | G9: 1 | H9: 0 | I9: 1 | J9: 2 | K9: 3 | L9: 4 | M9: 4
A11: REVENUE
A12: Baseline business | B12: =Assumptions!$B$4*(B5/100) -> 4140 | C12: =Assumptions!$B$4*(C5/100) -> 4095 | D12: =Assumptions!$B$4*(D5/100) -> 4455 | E12: =Assumptions!$B$4*(E5/100) -> 4230 | F12: =Assumptions!$B$4*(F5/100) -> 3285 | G12: =Assumptions!$B$4*(G5/100) -> 2160 | H12: =Assumptions!$B$4*(H5/100) -> 1035 | I12: =Assumptions!$B$4*(I5/100) -> 1260 | ... M12: =Assumptions!$B$4*(M5/100) -> 4500
A13: Weekday-capacity growth | B13: =B6 -> 0 | C13: =C6 -> 500 | D13: =D6 -> 1000 | E13: =E6 -> 1200 | F13: =F6 -> 800 | G13: =G6 -> 400 | H13: =H6 -> 200 | I13: =I6 -> 400 | ... M13: =M6 -> 1800
A14: New mowing cohort (Spring 2027) | B14: =B8*B9*Assumptions!$B$17 -> 0 | C14: =C8*C9*Assumptions!$B$17 -> 0 | D14: =D8*D9*Assumptions!$B$17 -> 0 | E14: =E8*E9*Assumptions!$B$17 -> 0 | F14: =F8*F9*Assumptions!$B$17 -> 0 | G14: =G8*G9*Assumptions!$B$17 -> 0 | H14: =H8*H9*Assumptions!$B$17 -> 0 | I14: =I8*I9*Assumptions!$B$17 -> 120 | ... M14: =M8*M9*Assumptions!$B$17 -> 2880
A15: TOTAL REVENUE | B15: =SUM(B12:B14) -> 4140 | C15: =SUM(C12:C14) -> 4595 | D15: =SUM(D12:D14) -> 5455 | E15: =SUM(E12:E14) -> 5430 | F15: =SUM(F12:F14) -> 4085 | G15: =SUM(G12:G14) -> 2560 | H15: =SUM(H12:H14) -> 1235 | I15: =SUM(I12:I14) -> 1780 | ... M15: =SUM(M12:M14) -> 9180
A17: CONTRIBUTION MARGIN
A18: Baseline contribution | B18: =B12*Assumptions!$B$13 -> 1570.716 | C18: =C12*Assumptions!$B$13 -> 1553.643 | D18: =D12*Assumptions!$B$13 -> 1690.227 | E18: =E12*Assumptions!$B$13 -> 1604.862 | F18: =F12*Assumptions!$B$13 -> 1246.329 | G18: =G12*Assumptions!$B$13 -> 819.504 | H18: =H12*Assumptions!$B$13 -> 392.679 | I18: =I12*Assumptions!$B$13 -> 478.044 | ... M18: =M12*Assumptions!$B$13 -> 1707.3
A19: Weekday contribution | B19: =B13*Assumptions!$B$12 -> 0 | C19: =C13*Assumptions!$B$12 -> 190 | D19: =D13*Assumptions!$B$12 -> 380 | E19: =E13*Assumptions!$B$12 -> 456 | F19: =F13*Assumptions!$B$12 -> 304 | G19: =G13*Assumptions!$B$12 -> 152 | H19: =H13*Assumptions!$B$12 -> 76 | I19: =I13*Assumptions!$B$12 -> 152 | ... M19: =M13*Assumptions!$B$12 -> 684
A20: New mowing contribution | B20: =B14*Assumptions!$B$11 -> 0 | C20: =C14*Assumptions!$B$11 -> 0 | D20: =D14*Assumptions!$B$11 -> 0 | E20: =E14*Assumptions!$B$11 -> 0 | F20: =F14*Assumptions!$B$11 -> 0 | G20: =G14*Assumptions!$B$11 -> 0 | H20: =H14*Assumptions!$B$11 -> 0 | I20: =I14*Assumptions!$B$11 -> 62.4 | ... M20: =M14*Assumptions!$B$11 -> 1497.6
A21: TOTAL CONTRIBUTION | B21: =SUM(B18:B20) -> 1570.716 | C21: =SUM(C18:C20) -> 1743.643 | D21: =SUM(D18:D20) -> 2070.227 | E21: =SUM(E18:E20) -> 2060.862 | F21: =SUM(F18:F20) -> 1550.329 | G21: =SUM(G18:G20) -> 971.504 | H21: =SUM(H18:H20) -> 468.679 | I21: =SUM(I18:I20) -> 692.444 | ... M21: =SUM(M18:M20) -> 3888.9
A23: PROFIT
A24: Less: fixed monthly costs | B24: =-Assumptions!$B$26 -> -695.06 | C24: =-Assumptions!$B$26 -> -695.06 | D24: =-Assumptions!$B$26 -> -695.06 | E24: =-Assumptions!$B$26 -> -695.06 | F24: =-Assumptions!$B$26 -> -695.06 | G24: =-Assumptions!$B$26 -> -695.06 | H24: =-Assumptions!$B$26 -> -695.06 | I24: =-Assumptions!$B$26 -> -695.06 | ... M24: =-Assumptions!$B$26 -> -695.06
A25: NET PROFIT | B25: =B21+B24 -> 875.656 | C25: =C21+C24 -> 1048.583 | D25: =D21+D24 -> 1375.167 | E25: =E21+E24 -> 1365.802 | F25: =F21+F24 -> 855.269 | G25: =G21+G24 -> 276.444 | H25: =H21+H24 -> -226.381 | I25: =I21+I24 -> -2.616 | ... M25: =M21+M24 -> 3193.84
A26: Net margin % | B26: =IF(B15=0,0,B25/B15) -> 0.21151111 | C26: =IF(C15=0,0,C25/C15) -> 0.22820087 | D26: =IF(D15=0,0,D25/D15) -> 0.25209294 | E26: =IF(E15=0,0,E25/E15) -> 0.25152891 | F26: =IF(F15=0,0,F25/F15) -> 0.20936818 | G26: =IF(G15=0,0,G25/G15) -> 0.10798594 | H26: =IF(H15=0,0,H25/H15) -> -0.18330445 | I26: =IF(I15=0,0,I25/I15) -> -0.0014696629 | ... M26: =IF(M15=0,0,M25/M15) -> 0.34791285
A28: CAPITAL & CASH
A29: Capital outflows | B29: =-Assumptions!$B$36 -> 0 | C29: 0 | D29: =-Assumptions!$B$37 -> -400 | E29: 0 | F29: 0 | G29: 0 | H29: 0 | I29: 0 | J29: =-Assumptions!$B$38 -> -1500 | K29: 0 | L29: 0 | M29: 0
A30: Net cash flow | B30: =B25+B29 -> 875.656 | C30: =C25+C29 -> 1048.583 | D30: =D25+D29 -> 975.167 | E30: =E25+E29 -> 1365.802 | F30: =F25+F29 -> 855.269 | G30: =G25+G29 -> 276.444 | H30: =H25+H29 -> -226.381 | I30: =I25+I29 -> -2.616 | ... M30: =M25+M29 -> 3193.84
A31: CASH ON HAND (end of month) | B31: =Assumptions!$B$33+B30 -> 2375.656 | C31: =B31+C30 -> 3424.239 | D31: =C31+D30 -> 4399.406 | E31: =D31+E30 -> 5765.208 | F31: =E31+F30 -> 6620.477 | G31: =F31+G30 -> 6896.921 | H31: =G31+H30 -> 6670.54 | I31: =H31+I30 -> 6667.924 | J31: =I31+J30 -> 6158.571 | ... M31: =L31+M30 -> 14580.396
A32: Cash above reserve + cushion | B32: =B31-Assumptions!$B$34-Assumptions!$B$35 -> -3624.344 | C32: =C31-Assumptions!$B$34-Assumptions!$B$35 -> -2575.761 | D32: =D31-Assumptions!$B$34-Assumptions!$B$35 -> -1600.594 | E32: =E31-Assumptions!$B$34-Assumptions!$B$35 -> -234.792 | F32: =F31-Assumptions!$B$34-Assumptions!$B$35 -> 620.477 | G32: =G31-Assumptions!$B$34-Assumptions!$B$35 -> 896.921 | H32: =H31-Assumptions!$B$34-Assumptions!$B$35 -> 670.54 | I32: =I31-Assumptions!$B$34-Assumptions!$B$35 -> 667.924 | ... M32: =M31-Assumptions!$B$34-Assumptions!$B$35 -> 8580.396
A34: Note: Truck debt ($3,800, no interest, owed to owner) is deferrable and excluded from the base cash line; repay opportunistically from surplus once reserve, cushion and Xavier payout are satisfied.

Sheet Quarterly Summary
A1: QUARTERLY SUMMARY
B3: Q3 2026 (Jul–Sep) | C3: Q4 2026 (Oct–Dec) | D3: Q1 2027 (Jan–Mar) | E3: Q2 2027 (Apr–Jun)
A4: Total revenue | B4: =SUM(Model!B15:D15) -> 14190 | C4: =SUM(Model!E15:G15) -> 12075 | D4: =SUM(Model!H15:J15) -> 7190 | E4: =SUM(Model!K15:M15) -> 24885
A5: Net profit | B5: =SUM(Model!B25:D25) -> 3299.406 | C5: =SUM(Model!E25:G25) -> 2497.515 | D5: =SUM(Model!H25:J25) -> 761.65 | E5: =SUM(Model!K25:M25) -> 8421.825
A6: Avg. monthly net margin | B6: =AVERAGE(Model!B26:D26) -> 0.23060164 | C6: =AVERAGE(Model!E26:G26) -> 0.18962768 | D6: =AVERAGE(Model!H26:J26) -> 0.017502201 | E6: =AVERAGE(Model!K26:M26) -> 0.33649607
A7: Cash on hand (quarter-end) | B7: =Model!D31 -> 4399.406 | C7: =Model!G31 -> 6896.921 | D7: =Model!J31 -> 6158.571 | E7: =Model!M31 -> 14580.396
A9: KEY MILESTONES
A10: Q3 2026 | B10: Reserve crosses $4,000 (~Sep); begin lead recruiting & Homeworks activation; start lead capture.
A11: Q4 2026 | B11: Electric blower for leaf season; recruit/train weekday lead; fall pre-sell push; build GBP/reviews/yard signs; registered-agent change.
A12: Q1 2027 | B12: Owner relocates (Jan); spring acquisition campaign fires (Feb–Mar); Xavier payout (Mar); new mowing cohort begins onboarding.
A13: Q2 2027 | B13: Spring cohort matures; weekday routes scale; owner returns (~mid-May) to lead peak; revenue approaches ~$9K/month.

Sheet P&L Tracker
A1: P&L TRACKER — PLAN vs ACTUAL
A2: Enter ACTUALS in the blue rows each month; plan and variance update automatically.
A4: ($ per month) | B4: Jul-26 | C4: Aug-26 | D4: Sep-26 | E4: Oct-26 | F4: Nov-26 | G4: Dec-26 | H4: Jan-27 | I4: Feb-27 | J4: Mar-27 | K4: Apr-27 | L4: May-27 | M4: Jun-27
A5: PLAN (from Model tab)
A6: Plan revenue | B6: =Model!B15 -> 4140 | C6: =Model!C15 -> 4595 | D6: =Model!D15 -> 5455 | E6: =Model!E15 -> 5430 | F6: =Model!F15 -> 4085 | G6: =Model!G15 -> 2560 | H6: =Model!H15 -> 1235 | I6: =Model!I15 -> 1780 | ... M6: =Model!M15 -> 9180
A7: Plan net profit | B7: =Model!B25 -> 875.656 | C7: =Model!C25 -> 1048.583 | D7: =Model!D25 -> 1375.167 | E7: =Model!E25 -> 1365.802 | F7: =Model!F25 -> 855.269 | G7: =Model!G25 -> 276.444 | H7: =Model!H25 -> -226.381 | I7: =Model!I25 -> -2.616 | ... M7: =Model!M25 -> 3193.84
A9: ACTUAL — REVENUE (enter below)
A10: Mowing revenue | B10: 0 | C10: 0 | D10: 0 | E10: 0 | F10: 0 | G10: 0 | H10: 0 | I10: 0 | J10: 0 | K10: 0 | L10: 0 | M10: 0
A11: Project revenue | B11: 0 | C11: 0 | D11: 0 | E11: 0 | F11: 0 | G11: 0 | H11: 0 | I11: 0 | J11: 0 | K11: 0 | L11: 0 | M11: 0
A12: Other revenue | B12: 0 | C12: 0 | D12: 0 | E12: 0 | F12: 0 | G12: 0 | H12: 0 | I12: 0 | J12: 0 | K12: 0 | L12: 0 | M12: 0
A13: Total actual revenue | B13: =SUM(B10:B12) -> 0 | C13: =SUM(C10:C12) -> 0 | D13: =SUM(D10:D12) -> 0 | E13: =SUM(E10:E12) -> 0 | F13: =SUM(F10:F12) -> 0 | G13: =SUM(G10:G12) -> 0 | H13: =SUM(H10:H12) -> 0 | I13: =SUM(I10:I12) -> 0 | ... M13: =SUM(M10:M12) -> 0
A15: ACTUAL — COSTS (enter below)
A16: Labor | B16: 0 | C16: 0 | D16: 0 | E16: 0 | F16: 0 | G16: 0 | H16: 0 | I16: 0 | J16: 0 | K16: 0 | L16: 0 | M16: 0
A17: Fuel | B17: 0 | C17: 0 | D17: 0 | E17: 0 | F17: 0 | G17: 0 | H17: 0 | I17: 0 | J17: 0 | K17: 0 | L17: 0 | M17: 0
A18: Materials / equipment | B18: 0 | C18: 0 | D18: 0 | E18: 0 | F18: 0 | G18: 0 | H18: 0 | I18: 0 | J18: 0 | K18: 0 | L18: 0 | M18: 0
A19: Total direct cost | B19: =SUM(B16:B18) -> 0 | C19: =SUM(C16:C18) -> 0 | D19: =SUM(D16:D18) -> 0 | E19: =SUM(E16:E18) -> 0 | F19: =SUM(F16:F18) -> 0 | G19: =SUM(G16:G18) -> 0 | H19: =SUM(H16:H18) -> 0 | I19: =SUM(I16:I18) -> 0 | ... M19: =SUM(M16:M18) -> 0
A20: Fixed costs | B20: =Assumptions!$B$26 -> 695.06 | C20: =Assumptions!$B$26 -> 695.06 | D20: =Assumptions!$B$26 -> 695.06 | E20: =Assumptions!$B$26 -> 695.06 | F20: =Assumptions!$B$26 -> 695.06 | G20: =Assumptions!$B$26 -> 695.06 | H20: =Assumptions!$B$26 -> 695.06 | I20: =Assumptions!$B$26 -> 695.06 | ... M20: =Assumptions!$B$26 -> 695.06
A21: ACTUAL NET PROFIT | B21: =B13-B19-B20 -> -695.06 | C21: =C13-C19-C20 -> -695.06 | D21: =D13-D19-D20 -> -695.06 | E21: =E13-E19-E20 -> -695.06 | F21: =F13-F19-F20 -> -695.06 | G21: =G13-G19-G20 -> -695.06 | H21: =H13-H19-H20 -> -695.06 | I21: =I13-I19-I20 -> -695.06 | ... M21: =M13-M19-M20 -> -695.06
A23: VARIANCE (actual − plan)
A24: Revenue variance | B24: =B13-B6 -> -4140 | C24: =C13-C6 -> -4595 | D24: =D13-D6 -> -5455 | E24: =E13-E6 -> -5430 | F24: =F13-F6 -> -4085 | G24: =G13-G6 -> -2560 | H24: =H13-H6 -> -1235 | I24: =I13-I6 -> -1780 | ... M24: =M13-M6 -> -9180
A25: Profit variance | B25: =B21-B7 -> -1570.716 | C25: =C21-C7 -> -1743.643 | D25: =D21-D7 -> -2070.227 | E25: =E21-E7 -> -2060.862 | F25: =F21-F7 -> -1550.329 | G25: =G21-G7 -> -971.504 | H25: =H21-H7 -> -468.679 | I25: =I21-I7 -> -692.444 | ... M25: =M21-M7 -> -3888.9
A27: Tip: as real data lands, update the Assumptions tab (margins, anchor, mix) so the Model plan converges toward reality.
